Workbook

Sheet cover
B3: Community studied: | C3: =df_geo!B2 -> #N/A
B4: Census subdivision #: | C4: =df_geo!A2 -> 1000000
B6: Region: | C6: =df_geo!B3 -> Canada
B7: Province: | C7: =df_geo!B4 -> #N/A
B9: Effective date: | C9: =TODAY() -> 46154

Sheet priorities
B2: VULNERABILITY PROFILE — COMMUNITY SNAPSHOT TEXT | E2: PRIORITY ISSUES — TOP RANKED VULNERABILITY CONCERNS
B3: The text below is auto-generated from the index results entered on the Inputs sheet. Copy the relevant cells into the Community Snapshot as needed. Not all indices need to appear — include those most pertinent to the community's profile. | E3: Show top: | F3: 5 | G3: ← Change this number to show more or fewer issues (1–8)
B4: Index | C4: Generated narrative text | E4: Rank | F4: Issues | G4: Implication
B5: Residential instability | C5: =IFERROR(SUBSTITUTE(textlib!G2&" "&INDEX(textlib!B2:F2,MATCH(vuln!I36,{"Low","Below average","Average","Above average","High"},0)),"[COMPARATOR]",vuln!K36),"Information unavailable") -> Information unavailable | E5: =IF(1<=$F$3,1,"") -> 1 | F5: =IFERROR(IF(1<=$F$3,INDEX(vuln!$G$36:$G$43,MATCH(LARGE(vuln!$M$36:$M$43,1),vuln!$M$36:$M$43,0)),""),"Information unavailable") -> Information unavailable | G5: =IFERROR(IF(1<=$F$3,SUBSTITUTE(INDEX(textlib!$G$2:$G$9,MATCH(LARGE(vuln!$M$36:$M$43,1),vuln!$M$36:$M$43,0))&" "&INDEX(textlib!$B$2:$F$9,MATCH(LARGE(vuln!$M$36:$M$43,1),vuln!$M$36:$M$43,0),MATCH(INDEX(vuln!$I$36:$I$43,MATCH(LARGE(vuln!$M$36:$M$43,1),vuln!$M$36:$M$43,0)),{"Low","Below average","Average","Above average","High"},0)),"[COMPARATOR]",INDEX(vuln!$K$36:$K$43,MATCH(LARGE(vuln!$M$36:$M$43,1),vuln!$M$36:$M$43,0))),"" ),"Information unavailable") -> Information unavailable
B6: Economic dependency | C6: =IFERROR(SUBSTITUTE(textlib!G3&" "&INDEX(textlib!B3:F3,MATCH(vuln!I37,{"Low","Below average","Average","Above average","High"},0)),"[COMPARATOR]",vuln!K37),"Information unavailable") -> Information unavailable | E6: =IF(2<=$F$3,2,"") -> 2 | F6: =IFERROR(IF(2<=$F$3,INDEX(vuln!$G$36:$G$43,MATCH(LARGE(vuln!$M$36:$M$43,2),vuln!$M$36:$M$43,0)),""),"Information unavailable") -> Information unavailable | G6: =IFERROR(IF(2<=$F$3,SUBSTITUTE(INDEX(textlib!$G$2:$G$9,MATCH(LARGE(vuln!$M$36:$M$43,2),vuln!$M$36:$M$43,0))&" "&INDEX(textlib!$B$2:$F$9,MATCH(LARGE(vuln!$M$36:$M$43,2),vuln!$M$36:$M$43,0),MATCH(INDEX(vuln!$I$36:$I$43,MATCH(LARGE(vuln!$M$36:$M$43,2),vuln!$M$36:$M$43,0)),{"Low","Below average","Average","Above average","High"},0)),"[COMPARATOR]",INDEX(vuln!$K$36:$K$43,MATCH(LARGE(vuln!$M$36:$M$43,2),vuln!$M$36:$M$43,0))),"" ),"Information unavailable") -> Information unavailable
B7: Ethno-cultural composition | C7: =IFERROR(SUBSTITUTE(textlib!G4&" "&INDEX(textlib!B4:F4,MATCH(vuln!I38,{"Low","Below average","Average","Above average","High"},0)),"[COMPARATOR]",vuln!K38),"Information unavailable") -> Information unavailable | E7: =IF(3<=$F$3,3,"") -> 3 | F7: =IFERROR(IF(3<=$F$3,INDEX(vuln!$G$36:$G$43,MATCH(LARGE(vuln!$M$36:$M$43,3),vuln!$M$36:$M$43,0)),""),"Information unavailable") -> Information unavailable | G7: =IFERROR(IF(3<=$F$3,SUBSTITUTE(INDEX(textlib!$G$2:$G$9,MATCH(LARGE(vuln!$M$36:$M$43,3),vuln!$M$36:$M$43,0))&" "&INDEX(textlib!$B$2:$F$9,MATCH(LARGE(vuln!$M$36:$M$43,3),vuln!$M$36:$M$43,0),MATCH(INDEX(vuln!$I$36:$I$43,MATCH(LARGE(vuln!$M$36:$M$43,3),vuln!$M$36:$M$43,0)),{"Low","Below average","Average","Above average","High"},0)),"[COMPARATOR]",INDEX(vuln!$K$36:$K$43,MATCH(LARGE(vuln!$M$36:$M$43,3),vuln!$M$36:$M$43,0))),"" ),"Information unavailable") -> Information unavailable
B8: Situational vulnerability | C8: =IFERROR(SUBSTITUTE(textlib!G5&" "&INDEX(textlib!B5:F5,MATCH(vuln!I39,{"Low","Below average","Average","Above average","High"},0)),"[COMPARATOR]",vuln!K39),"Information unavailable") -> Information unavailable | E8: =IF(4<=$F$3,4,"") -> 4 | F8: =IFERROR(IF(4<=$F$3,INDEX(vuln!$G$36:$G$43,MATCH(LARGE(vuln!$M$36:$M$43,4),vuln!$M$36:$M$43,0)),""),"Information unavailable") -> Information unavailable | G8: =IFERROR(IF(4<=$F$3,SUBSTITUTE(INDEX(textlib!$G$2:$G$9,MATCH(LARGE(vuln!$M$36:$M$43,4),vuln!$M$36:$M$43,0))&" "&INDEX(textlib!$B$2:$F$9,MATCH(LARGE(vuln!$M$36:$M$43,4),vuln!$M$36:$M$43,0),MATCH(INDEX(vuln!$I$36:$I$43,MATCH(LARGE(vuln!$M$36:$M$43,4),vuln!$M$36:$M$43,0)),{"Low","Below average","Average","Above average","High"},0)),"[COMPARATOR]",INDEX(vuln!$K$36:$K$43,MATCH(LARGE(vuln!$M$36:$M$43,4),vuln!$M$36:$M$43,0))),"" ),"Information unavailable") -> Information unavailable
B9: Social resilience | C9: =IFERROR(SUBSTITUTE(textlib!G6&" "&INDEX(textlib!B6:F6,MATCH(vuln!I40,{"Low","Below average","Average","Above average","High"},0)),"[COMPARATOR]",vuln!K40),"Information unavailable") -> Information unavailable | E9: =IF(5<=$F$3,5,"") -> 5 | F9: =IFERROR(IF(5<=$F$3,INDEX(vuln!$G$36:$G$43,MATCH(LARGE(vuln!$M$36:$M$43,5),vuln!$M$36:$M$43,0)),""),"Information unavailable") -> Information unavailable | G9: =IFERROR(IF(5<=$F$3,SUBSTITUTE(INDEX(textlib!$G$2:$G$9,MATCH(LARGE(vuln!$M$36:$M$43,5),vuln!$M$36:$M$43,0))&" "&INDEX(textlib!$B$2:$F$9,MATCH(LARGE(vuln!$M$36:$M$43,5),vuln!$M$36:$M$43,0),MATCH(INDEX(vuln!$I$36:$I$43,MATCH(LARGE(vuln!$M$36:$M$43,5),vuln!$M$36:$M$43,0)),{"Low","Below average","Average","Above average","High"},0)),"[COMPARATOR]",INDEX(vuln!$K$36:$K$43,MATCH(LARGE(vuln!$M$36:$M$43,5),vuln!$M$36:$M$43,0))),"" ),"Information unavailable") -> Information unavailable
B10: Social vulnerability | C10: =IFERROR(SUBSTITUTE(textlib!G7&" "&INDEX(textlib!B7:F7,MATCH(vuln!I41,{"Low","Below average","Average","Above average","High"},0)),"[COMPARATOR]",vuln!K41),"Information unavailable") -> Information unavailable | E10: =IF(6<=$F$3,6,"") | F10: =IF(6<=$F$3,INDEX(vuln!$G$36:$G$43,MATCH(LARGE(vuln!$M$36:$M$43,6),vuln!$M$36:$M$43,0)),"") | G10: =IFERROR(IF(6<=$F$3,SUBSTITUTE(INDEX(textlib!$G$2:$G$9,MATCH(LARGE(vuln!$M$36:$M$43,6),vuln!$M$36:$M$43,0))&" "&INDEX(textlib!$B$2:$F$9,MATCH(LARGE(vuln!$M$36:$M$43,6),vuln!$M$36:$M$43,0),MATCH(INDEX(vuln!$I$36:$I$43,MATCH(LARGE(vuln!$M$36:$M$43,6),vuln!$M$36:$M$43,0)),{"Low","Below average","Average","Above average","High"},0)),"[COMPARATOR]",INDEX(vuln!$K$36:$K$43,MATCH(LARGE(vuln!$M$36:$M$43,6),vuln!$M$36:$M$43,0))),"" ),"Information unavailable")
B11: Material deprivation | C11: =IFERROR(SUBSTITUTE(textlib!G8&" "&INDEX(textlib!B8:F8,MATCH(vuln!I42,{"Low","Below average","Average","Above average","High"},0)),"[COMPARATOR]",vuln!K42),"Information unavailable") -> Information unavailable | E11: =IF(7<=$F$3,7,"") | F11: =IF(7<=$F$3,INDEX(vuln!$G$36:$G$43,MATCH(LARGE(vuln!$M$36:$M$43,7),vuln!$M$36:$M$43,0)),"") | G11: =IFERROR(IF(7<=$F$3,SUBSTITUTE(INDEX(textlib!$G$2:$G$9,MATCH(LARGE(vuln!$M$36:$M$43,7),vuln!$M$36:$M$43,0))&" "&INDEX(textlib!$B$2:$F$9,MATCH(LARGE(vuln!$M$36:$M$43,7),vuln!$M$36:$M$43,0),MATCH(INDEX(vuln!$I$36:$I$43,MATCH(LARGE(vuln!$M$36:$M$43,7),vuln!$M$36:$M$43,0)),{"Low","Below average","Average","Above average","High"},0)),"[COMPARATOR]",INDEX(vuln!$K$36:$K$43,MATCH(LARGE(vuln!$M$36:$M$43,7),vuln!$M$36:$M$43,0))),"" ),"Information unavailable")
B12: Social deprivation | C12: =IFERROR(SUBSTITUTE(textlib!G9&" "&INDEX(textlib!B9:F9,MATCH(vuln!I43,{"Low","Below average","Average","Above average","High"},0)),"[COMPARATOR]",vuln!K43),"Information unavailable") -> Information unavailable | E12: =IF(8<=$F$3,8,"") | F12: =IF(8<=$F$3,INDEX(vuln!$G$36:$G$43,MATCH(LARGE(vuln!$M$36:$M$43,8),vuln!$M$36:$M$43,0)),"") | G12: =IFERROR(IF(8<=$F$3,SUBSTITUTE(INDEX(textlib!$G$2:$G$9,MATCH(LARGE(vuln!$M$36:$M$43,8),vuln!$M$36:$M$43,0))&" "&INDEX(textlib!$B$2:$F$9,MATCH(LARGE(vuln!$M$36:$M$43,8),vuln!$M$36:$M$43,0),MATCH(INDEX(vuln!$I$36:$I$43,MATCH(LARGE(vuln!$M$36:$M$43,8),vuln!$M$36:$M$43,0)),{"Low","Below average","Average","Above average","High"},0)),"[COMPARATOR]",INDEX(vuln!$K$36:$K$43,MATCH(LARGE(vuln!$M$36:$M$43,8),vuln!$M$36:$M$43,0))),"" ),"Information unavailable")
B14: Source: Canadian Index of Multiple Deprivation (CIMD), Canadian Index of Social Resilience (CISR), Canadian Index of Social Vulnerability (CISV), Material and Social Deprivation Index (MSDI). Results derived from 2021 Census dissemination area data. Note: Social resilience is inverted — high resilience is a favourable outcome. | E14: Ranking is based on the provincial quintile result. Social resilience is inverted (low resilience ranks as high severity). Where two indices share the same quintile result, the index appearing earlier in the table ranks first. All eight indices are available on the Generated Text sheet.

Sheet summary
B4: DEMOGRAPHIC PROFILE | F4: ECONOMIC PROFILE
B5: =IFERROR(popn_fut!$M$35,"x") -> x | C5: =IFERROR(popn_now!F36,"x") -> x | D5: =IFERROR(popn_now!F37,"x") -> 0 | F5: {=IFERROR(income!$C$40,"x")} -> x | G5: =IFERROR(income!$C$45,"x") -> x | H5: =IFERROR(econ!$C$63,"x") -> x
B6: Total population (2025) | C6: Population change (2021-2025) | D6: Change to 0 to 14 year olds (2021-2025) | F6: Median before-tax household income (2020) | G6: Before-tax single person income (2020) | H6: ="Largest employer: " & econ!N38 -> Largest employer:
B7: =IFERROR(popn_now!F45,"x") -> x | C7: =IFERROR(popn_now!F46,"x") -> x | D7: =IFERROR(popn_now!J152,"x") -> x | F7: {=IFERROR(ABS(econ!J93),"x")} -> 0 | G7: =IFERROR(econ!$C$24,"x") -> x | H7: =IFERROR(IF(econ!C26 = 0, "x", econ!C26),0) -> x
B8: Change to 15 to 34 year olds (2021-2025) | C8: Change to 65+ year olds (2021-2025) | D8: Share of population that moved to the community between 2016-2021 | F8: ="Net " & IF(econ!J93<0,"outflow","inflow") & " of commuters (2021)" -> Net inflow of commuters (2021) | G8: Persons 15+ in the labour force (2021) | H8: Persons 15+ unemployed (2021)
B9: =popn_now!C195 -> x | C9: =popn_now!C196 -> x | D9: =popn_now!C194 -> x | F9: =income!$C$142 -> x | G9: =IFERROR(IF(SUM(income!D99:E99) = 0, "x", SUM(income!D99:E99)),"x") -> x | H9: =sales!C44 -> x
B10: Visible minority identifying persons (2021) | C10: Immigrants (2021) | D10: Indigenous identifying persons (2021) | F10: Persons living below the poverty line (2021) | G10: Households with very-low or low incomes | H10: Change in province-wide wage/salaries (2019-2024)
B11: {=IFERROR(hh!C39,"x")} -> x | C11: =hh!D39 -> x | D11: {=IF(hh!E39=0,"x",hh!E39)} -> x
B12: Total households (2021) | C12: Owner households (2021) | D12: Renter households (2021)
B13: =IFERROR(hh!F56,"x") -> x | C13: =hh!F52 -> x | D13: =IF(hh!G90>0,hh!G90,"x") -> x
B14: Single person households (2021) | C14: Lone parent households (2021) | D14: Suppressed 25 to 34 year old led households (2021)
B17: HOUSING PROFILE | F17: HOUSING NEED
B18: =IFERROR(dwell!N17,"x") -> x | C18: =IFERROR(1-dwell!C50/dwell!N17,"x") -> x | D18: =dwell!F103 -> x | F18: =need!C107 -> x | G18: =need!C108 -> x | H18: =need!C109 -> x
B19: Total dwellings (2021) | C19: Not occupied by usual residents (e.g., vacant, STRs, second homes - 2021) | D19: Single-detached dwellings (2021) | F19: Overcrowded households (2021) | G19: Dwellings needing major repair (2021) | H19: Dwellings deemed unaffordable (2021)
B20: =IFERROR(IF(AVERAGE(dwell!C17:H17) = 0, "x", AVERAGE(dwell!C17:H17)),"x") -> x | C20: =IFERROR(SUM(dwell!F51:F52),"x") -> x | D20: =IFERROR(SUM(dwell!C287:D287),"x") -> 0 | F20: =need!C111 -> x | G20: =need!D111 -> x | H20: =need!E111 -> x
B21: Average annual permit totals (2018-2023) | C21: Dwellings built pre-1980 | D21: Estimated dwellings with moderate to high flood susceptibility | F21: Total households in core housing need (2021) | G21: Owner households in core housing need (2021) | H21: Renter households in core housing need (2021)
B22: =rental!C34 -> x | C22: =IF(rental!D34="x",rental!F34,rental!D34) -> x | D22: =dwell!C181 -> x | F22: =IFERROR(need!E199/need!D199,"x") -> x | G22: =IFERROR(SUM(need!D200:D201)/need!D199,"x") -> x | H22: =need!C112 -> x
B23: Change in average rents (2020-2025) | C23: =IF(rental!D34="x","Provincial","Local") & " rental vacancy rate" -> Provincial rental vacancy rate | D23: Rentals considered affordable (2021) | F23: Households in core need that are single persons (2021) | G23: Households in core need that are very low or low income earning (2021) | H23: Total households in extreme core housing need (2021)
B24: =IFERROR(IF(dwell!H189 = 0, "x", dwell!H189),"x") -> x | C24: =sales!D34 -> x | D24: =IFERROR(dwell!D256,"x") -> x
B25: Change in affordable rentals (2016-2021) | C25: Change in average sale prices (2020-2025) | D25: Estimated short-term rentals that are potentially long-term housing (2025)
B26: =dwell!C145 -> x | C26: =SUM(dwell!C374:D374) -> 0 | D26: =SUM(dwell!C377:D377) -> 0
B27: Renters living in subsidized housing (2021) | C27: Non-market housing inventory (beds and units) | D27: Shelter spaces for various population groups
B30: UNIT DEMAND / PROJECTED NEEDS
B31: =IFERROR(popn_fut!D81,"x") -> x | C31: =IFERROR(popn_fut!S81,"x") -> 0 | D31: =IFERROR(popn_fut!S82,"x") -> 0
B32: Projected population (2035) | C32: Projected population change (2025-2035) | D32: Change to 0 to 14 year olds (2025-2035)
B33: =IFERROR(popn_fut!S90,"x") -> x | C33: =IFERROR(popn_fut!S91,"x") -> x | D33: =IFERROR(projection!D72,"x") -> x
B34: Change to 15 to 34 year olds (2021-2025) | C34: Change to 65+ year olds (2021-2025) | D34: Estimated 2025 dwelling deficit
B35: =IFERROR(projection!E354,"x") -> x | C35: =IFERROR(1-projection!E362/projection!E365,"x") -> x | D35: {=IFERROR(SUM(projection!G273:G277)/SUM(projection!C273:C277),"x")} -> x
B36: Projected total new dwelling demand (2025-2035) | C36: Demand for affordable units (2025-2035) | D36: Demand for rental units (2025-2035)
B37: =IFERROR(ABS(projection!E460),"x") -> x | C37: =MAX(projection!D529,projection!D528) -> 0
B38: ="Potential "& IF(projection!E460<0,"outflow","inflow") & " of unit demand from employment pressures (2025)" -> Potential inflow of unit demand from employment pressures (2025) | C38: Total maximum senior housing bed/unit demand (by 2035)

Sheet projection
A1: CSD | B1: CD | C1: PR | D1: Scenario
A2: =df_geo!A2 -> 1000000 | B2: =_xlfn.NUMBERVALUE(LEFT(A2,4)) -> 1000 | C2: =_xlfn.NUMBERVALUE(LEFT(B2,2)) -> 10 | D2: =popn_fut!D2 -> #N/A
B5: DEMOGRAPHIC PROJECTIONS
B7: ESTIMATED POPULATION
C8: 2015 | D8: 2016 | E8: 2017 | F8: 2018 | G8: 2019 | H8: 2020 | I8: 2021 | J8: 2022 | K8: 2023 | L8: 2024 | M8: 2025 | N8: 2026 | O8: 2027 | P8: 2028 | Q8: 2029 | R8: 2030 | S8: 2031 | T8: 2032 | U8: 2033 | V8: 2034 | W8: 2035 | X8: 2036 | Y8: 2037 | Z8: 2038 | AA8: 2039 | AB8: 2040 | AC8: 2041 | AD8: 2042 | AE8: 2043 | AF8: 2044 | AG8: 2045 | AH8: 2046 | AI8: 2047 | AJ8: 2048 | AK8: 2049 | AL8: 2050
B9: Total | C9: {=INDEX(df_est_csd!$C$2:$BA$10, MATCH($A$2, df_est_csd!$B$2:$B$10, 0), MATCH(TEXT(C$8, "####"), df_est_csd!$C$1:$BA$1, 0))} -> #N/A | D9: {=INDEX(df_est_csd!$C$2:$BA$10, MATCH($A$2, df_est_csd!$B$2:$B$10, 0), MATCH(TEXT(D$8, "####"), df_est_csd!$C$1:$BA$1, 0))} -> #N/A | E9: {=INDEX(df_est_csd!$C$2:$BA$10, MATCH($A$2, df_est_csd!$B$2:$B$10, 0), MATCH(TEXT(E$8, "####"), df_est_csd!$C$1:$BA$1, 0))} -> #N/A | F9: {=INDEX(df_est_csd!$C$2:$BA$10, MATCH($A$2, df_est_csd!$B$2:$B$10, 0), MATCH(TEXT(F$8, "####"), df_est_csd!$C$1:$BA$1, 0))} -> #N/A | G9: {=INDEX(df_est_csd!$C$2:$BA$10, MATCH($A$2, df_est_csd!$B$2:$B$10, 0), MATCH(TEXT(G$8, "####"), df_est_csd!$C$1:$BA$1, 0))} -> #N/A | H9: {=INDEX(df_est_csd!$C$2:$BA$10, MATCH($A$2, df_est_csd!$B$2:$B$10, 0), MATCH(TEXT(H$8, "####"), df_est_csd!$C$1:$BA$1, 0))} -> #N/A | I9: {=INDEX(df_est_csd!$C$2:$BA$10, MATCH($A$2, df_est_csd!$B$2:$B$10, 0), MATCH(TEXT(I$8, "####"), df_est_csd!$C$1:$BA$1, 0))} -> #N/A | J9: {=INDEX(df_est_csd!$C$2:$BA$10, MATCH($A$2, df_est_csd!$B$2:$B$10, 0), MATCH(TEXT(J$8, "####"), df_est_csd!$C$1:$BA$1, 0))} -> #N/A | ... M9: {=INDEX(df_est_csd!$C$2:$BA$10, MATCH($A$2, df_est_csd!$B$2:$B$10, 0), MATCH(TEXT(M$8, "####"), df_est_csd!$C$1:$BA$1, 0))} -> #N/A | N9: {=IFERROR(MROUND(INDEX(df_proj!$E$2:$AD$1000, MATCH(1, ($A$2 = df_proj!$A$2:$A$1000) * (df_proj!$B$2:$B$1000 = $B9) * (df_proj!$C$2:$C$1000 = $D$2), 0), MATCH(TEXT(N$8, "####"), df_proj!$E$1:$AD$1,0)),5),MROUND(INDEX(df_proj!$E$2:$AD$1000, MATCH(1, ($B$2 = df_proj!$A$2:$A$1000) * (df_proj!$B$2:$B$1000 = $B9) * (df_proj!$C$2:$C$1000 = $D$2), 0), MATCH(TEXT(N$8, "####"), df_proj!$E$1:$AD$1,0)) * popn_fut!$C81/popn_fut!$E81,5))} -> #N/A | O9: {=IFERROR(MROUND(INDEX(df_proj!$E$2:$AD$1000, MATCH(1, ($A$2 = df_proj!$A$2:$A$1000) * (df_proj!$B$2:$B$1000 = $B9) * (df_proj!$C$2:$C$1000 = $D$2), 0), MATCH(TEXT(O$8, "####"), df_proj!$E$1:$AD$1,0)),5),MROUND(INDEX(df_proj!$E$2:$AD$1000, MATCH(1, ($B$2 = df_proj!$A$2:$A$1000) * (df_proj!$B$2:$B$1000 = $B9) * (df_proj!$C$2:$C$1000 = $D$2), 0), MATCH(TEXT(O$8, "####"), df_proj!$E$1:$AD$1,0)) * popn_fut!$C81/popn_fut!$E81,5))} -> #N/A | P9: {=IFERROR(MROUND(INDEX(df_proj!$E$2:$AD$1000, MATCH(1, ($A$2 = df_proj!$A$2:$A$1000) * (df_proj!$B$2:$B$1000 = $B9) * (df_proj!$C$2:$C$1000 = $D$2), 0), MATCH(TEXT(P$8, "####"), df_proj!$E$1:$AD$1,0)),5),MROUND(INDEX(df_proj!$E$2:$AD$1000, MATCH(1, ($B$2 = df_proj!$A$2:$A$1000) * (df_proj!$B$2:$B$1000 = $B9) * (df_proj!$C$2:$C$1000 = $D$2), 0), MATCH(TEXT(P$8, "####"), df_proj!$E$1:$AD$1,0)) * popn_fut!$C81/popn_fut!$E81,5))} -> #N/A | Q9: {=IFERROR(MROUND(INDEX(df_proj!$E$2:$AD$1000, MATCH(1, ($A$2 = df_proj!$A$2:$A$1000) * (df_proj!$B$2:$B$1000 = $B9) * (df_proj!$C$2:$C$1000 = $D$2), 0), MATCH(TEXT(Q$8, "####"), df_proj!$E$1:$AD$1,0)),5),MROUND(INDEX(df_proj!$E$2:$AD$1000, MATCH(1, ($B$2 = df_proj!$A$2:$A$1000) * (df_proj!$B$2:$B$1000 = $B9) * (df_proj!$C$2:$C$1000 = $D$2), 0), MATCH(TEXT(Q$8, "####"), df_proj!$E$1:$AD$1,0)) * popn_fut!$C81/popn_fut!$E81,5))} -> #N/A | R9: {=IFERROR(MROUND(INDEX(df_proj!$E$2:$AD$1000, MATCH(1, ($A$2 = df_proj!$A$2:$A$1000) * (df_proj!$B$2:$B$1000 = $B9) * (df_proj!$C$2:$C$1000 = $D$2), 0), MATCH(TEXT(R$8, "####"), df_proj!$E$1:$AD$1,0)),5),MROUND(INDEX(df_proj!$E$2:$AD$1000, MATCH(1, ($B$2 = df_proj!$A$2:$A$1000) * (df_proj!$B$2:$B$1000 = $B9) * (df_proj!$C$2:$C$1000 = $D$2), 0), MATCH(TEXT(R$8, "####"), df_proj!$E$1:$AD$1,0)) * popn_fut!$C81/popn_fut!$E81,5))} -> #N/A | S9: {=IFERROR(MROUND(INDEX(df_proj!$E$2:$AD$1000, MATCH(1, ($A$2 = df_proj!$A$2:$A$1000) * (df_proj!$B$2:$B$1000 = $B9) * (df_proj!$C$2:$C$1000 = $D$2), 0), MATCH(TEXT(S$8, "####"), df_proj!$E$1:$AD$1,0)),5),MROUND(INDEX(df_proj!$E$2:$AD$1000, MATCH(1, ($B$2 = df_proj!$A$2:$A$1000) * (df_proj!$B$2:$B$1000 = $B9) * (df_proj!$C$2:$C$1000 = $D$2), 0), MATCH(TEXT(S$8, "####"), df_proj!$E$1:$AD$1,0)) * popn_fut!$C81/popn_fut!$E81,5))} -> #N/A | T9: {=IFERROR(MROUND(INDEX(df_proj!$E$2:$AD$1000, MATCH(1, ($A$2 = df_proj!$A$2:$A$1000) * (df_proj!$B$2:$B$1000 = $B9) * (df_proj!$C$2:$C$1000 = $D$2), 0), MATCH(TEXT(T$8, "####"), df_proj!$E$1:$AD$1,0)),5),MROUND(INDEX(df_proj!$E$2:$AD$1000, MATCH(1, ($B$2 = df_proj!$A$2:$A$1000) * (df_proj!$B$2:$B$1000 = $B9) * (df_proj!$C$2:$C$1000 = $D$2), 0), MATCH(TEXT(T$8, "####"), df_proj!$E$1:$AD$1,0)) * popn_fut!$C81/popn_fut!$E81,5))} -> #N/A | U9: {=IFERROR(MROUND(INDEX(df_proj!$E$2:$AD$1000, MATCH(1, ($A$2 = df_proj!$A$2:$A$1000) * (df_proj!$B$2:$B$1000 = $B9) * (df_proj!$C$2:$C$1000 = $D$2), 0), MATCH(TEXT(U$8, "####"), df_proj!$E$1:$AD$1,0)),5),MROUND(INDEX(df_proj!$E$2:$AD$1000, MATCH(1, ($B$2 = df_proj!$A$2:$A$1000) * (df_proj!$B$2:$B$1000 = $B9) * (df_proj!$C$2:$C$1000 = $D$2), 0), MATCH(TEXT(U$8, "####"), df_proj!$E$1:$AD$1,0)) * popn_fut!$C81/popn_fut!$E81,5))} -> #N/A | ... AL9: {=IFERROR(MROUND(INDEX(df_proj!$E$2:$AD$1000, MATCH(1, ($A$2 = df_proj!$A$2:$A$1000) * (df_proj!$B$2:$B$1000 = $B9) * (df_proj!$C$2:$C$1000 = $D$2), 0), MATCH(TEXT(AL$8, "####"), df_proj!$E$1:$AD$1,0)),5),MROUND(INDEX(df_proj!$E$2:$AD$1000, MATCH(1, ($B$2 = df_proj!$A$2:$A$1000) * (df_proj!$B$2:$B$1000 = $B9) * (df_proj!$C$2:$C$1000 = $D$2), 0), MATCH(TEXT(AL$8, "####"), df_proj!$E$1:$AD$1,0)) * popn_fut!$C81/popn_fut!$E81,5))} -> #N/A
A10: 0 | B10: 0 to 4 | D10: {=popn_now!J13:J30} -> #N/A | I10: {=popn_now!K13:K30} -> #N/A | M10: {=IFERROR(MROUND(INDEX(df_proj!$E$2:$AD$1000, MATCH(1, ($A$2 = df_proj!$A$2:$A$1000) * (df_proj!$B$2:$B$1000 = $B10) * (df_proj!$C$2:$C$1000 = $D$2), 0), MATCH(TEXT(M$8, "####"), df_proj!$E$1:$AD$1,0)),5),MROUND(INDEX(df_proj!$E$2:$AD$1000, MATCH(1, ($B$2 = df_proj!$A$2:$A$1000) * (df_proj!$B$2:$B$1000 = $B10) * (df_proj!$C$2:$C$1000 = $D$2), 0), MATCH(TEXT(M$8, "####"), df_proj!$E$1:$AD$1,0)) * popn_fut!$C82/popn_fut!$E82,5))} -> #N/A | N10: {=IFERROR(MROUND(INDEX(df_proj!$E$2:$AD$1000, MATCH(1, ($A$2 = df_proj!$A$2:$A$1000) * (df_proj!$B$2:$B$1000 = $B10) * (df_proj!$C$2:$C$1000 = $D$2), 0), MATCH(TEXT(N$8, "####"), df_proj!$E$1:$AD$1,0)),5),MROUND(INDEX(df_proj!$E$2:$AD$1000, MATCH(1, ($B$2 = df_proj!$A$2:$A$1000) * (df_proj!$B$2:$B$1000 = $B10) * (df_proj!$C$2:$C$1000 = $D$2), 0), MATCH(TEXT(N$8, "####"), df_proj!$E$1:$AD$1,0)) * popn_fut!$C82/popn_fut!$E82,5))} -> #N/A | O10: {=IFERROR(MROUND(INDEX(df_proj!$E$2:$AD$1000, MATCH(1, ($A$2 = df_proj!$A$2:$A$1000) * (df_proj!$B$2:$B$1000 = $B10) * (df_proj!$C$2:$C$1000 = $D$2), 0), MATCH(TEXT(O$8, "####"), df_proj!$E$1:$AD$1,0)),5),MROUND(INDEX(df_proj!$E$2:$AD$1000, MATCH(1, ($B$2 = df_proj!$A$2:$A$1000) * (df_proj!$B$2:$B$1000 = $B10) * (df_proj!$C$2:$C$1000 = $D$2), 0), MATCH(TEXT(O$8, "####"), df_proj!$E$1:$AD$1,0)) * popn_fut!$C82/popn_fut!$E82,5))} -> #N/A | P10: {=IFERROR(MROUND(INDEX(df_proj!$E$2:$AD$1000, MATCH(1, ($A$2 = df_proj!$A$2:$A$1000) * (df_proj!$B$2:$B$1000 = $B10) * (df_proj!$C$2:$C$1000 = $D$2), 0), MATCH(TEXT(P$8, "####"), df_proj!$E$1:$AD$1,0)),5),MROUND(INDEX(df_proj!$E$2:$AD$1000, MATCH(1, ($B$2 = df_proj!$A$2:$A$1000) * (df_proj!$B$2:$B$1000 = $B10) * (df_proj!$C$2:$C$1000 = $D$2), 0), MATCH(TEXT(P$8, "####"), df_proj!$E$1:$AD$1,0)) * popn_fut!$C82/popn_fut!$E82,5))} -> #N/A | Q10: {=IFERROR(MROUND(INDEX(df_proj!$E$2:$AD$1000, MATCH(1, ($A$2 = df_proj!$A$2:$A$1000) * (df_proj!$B$2:$B$1000 = $B10) * (df_proj!$C$2:$C$1000 = $D$2), 0), MATCH(TEXT(Q$8, "####"), df_proj!$E$1:$AD$1,0)),5),MROUND(INDEX(df_proj!$E$2:$AD$1000, MATCH(1, ($B$2 = df_proj!$A$2:$A$1000) * (df_proj!$B$2:$B$1000 = $B10) * (df_proj!$C$2:$C$1000 = $D$2), 0), MATCH(TEXT(Q$8, "####"), df_proj!$E$1:$AD$1,0)) * popn_fut!$C82/popn_fut!$E82,5))} -> #N/A | R10: {=IFERROR(MROUND(INDEX(df_proj!$E$2:$AD$1000, MATCH(1, ($A$2 = df_proj!$A$2:$A$1000) * (df_proj!$B$2:$B$1000 = $B10) * (df_proj!$C$2:$C$1000 = $D$2), 0), MATCH(TEXT(R$8, "####"), df_proj!$E$1:$AD$1,0)),5),MROUND(INDEX(df_proj!$E$2:$AD$1000, MATCH(1, ($B$2 = df_proj!$A$2:$A$1000) * (df_proj!$B$2:$B$1000 = $B10) * (df_proj!$C$2:$C$1000 = $D$2), 0), MATCH(TEXT(R$8, "####"), df_proj!$E$1:$AD$1,0)) * popn_fut!$C82/popn_fut!$E82,5))} -> #N/A | S10: {=IFERROR(MROUND(INDEX(df_proj!$E$2:$AD$1000, MATCH(1, ($A$2 = df_proj!$A$2:$A$1000) * (df_proj!$B$2:$B$1000 = $B10) * (df_proj!$C$2:$C$1000 = $D$2), 0), MATCH(TEXT(S$8, "####"), df_proj!$E$1:$AD$1,0)),5),MROUND(INDEX(df_proj!$E$2:$AD$1000, MATCH(1, ($B$2 = df_proj!$A$2:$A$1000) * (df_proj!$B$2:$B$1000 = $B10) * (df_proj!$C$2:$C$1000 = $D$2), 0), MATCH(TEXT(S$8, "####"), df_proj!$E$1:$AD$1,0)) * popn_fut!$C82/popn_fut!$E82,5))} -> #N/A | T10: {=IFERROR(MROUND(INDEX(df_proj!$E$2:$AD$1000, MATCH(1, ($A$2 = df_proj!$A$2:$A$1000) * (df_proj!$B$2:$B$1000 = $B10) * (df_proj!$C$2:$C$1000 = $D$2), 0), MATCH(TEXT(T$8, "####"), df_proj!$E$1:$AD$1,0)),5),MROUND(INDEX(df_proj!$E$2:$AD$1000, MATCH(1, ($B$2 = df_proj!$A$2:$A$1000) * (df_proj!$B$2:$B$1000 = $B10) * (df_proj!$C$2:$C$1000 = $D$2), 0), MATCH(TEXT(T$8, "####"), df_proj!$E$1:$AD$1,0)) * popn_fut!$C82/popn_fut!$E82,5))} -> #N/A | ... AL10: {=IFERROR(MROUND(INDEX(df_proj!$E$2:$AD$1000, MATCH(1, ($A$2 = df_proj!$A$2:$A$1000) * (df_proj!$B$2:$B$1000 = $B10) * (df_proj!$C$2:$C$1000 = $D$2), 0), MATCH(TEXT(AL$8, "####"), df_proj!$E$1:$AD$1,0)),5),MROUND(INDEX(df_proj!$E$2:$AD$1000, MATCH(1, ($B$2 = df_proj!$A$2:$A$1000) * (df_proj!$B$2:$B$1000 = $B10) * (df_proj!$C$2:$C$1000 = $D$2), 0), MATCH(TEXT(AL$8, "####"), df_proj!$E$1:$AD$1,0)) * popn_fut!$C82/popn_fut!$E82,5))} -> #N/A | AM10: =I10 -> #N/A | AP10: =W10 -> #N/A
A11: 5 | B11: 5 to 9 | D11: #N/A | I11: #N/A | M11: {=IFERROR(MROUND(INDEX(df_proj!$E$2:$AD$1000, MATCH(1, ($A$2 = df_proj!$A$2:$A$1000) * (df_proj!$B$2:$B$1000 = $B11) * (df_proj!$C$2:$C$1000 = $D$2), 0), MATCH(TEXT(M$8, "####"), df_proj!$E$1:$AD$1,0)),5),MROUND(INDEX(df_proj!$E$2:$AD$1000, MATCH(1, ($B$2 = df_proj!$A$2:$A$1000) * (df_proj!$B$2:$B$1000 = $B11) * (df_proj!$C$2:$C$1000 = $D$2), 0), MATCH(TEXT(M$8, "####"), df_proj!$E$1:$AD$1,0)) * popn_fut!$C83/popn_fut!$E83,5))} -> #N/A | N11: {=IFERROR(MROUND(INDEX(df_proj!$E$2:$AD$1000, MATCH(1, ($A$2 = df_proj!$A$2:$A$1000) * (df_proj!$B$2:$B$1000 = $B11) * (df_proj!$C$2:$C$1000 = $D$2), 0), MATCH(TEXT(N$8, "####"), df_proj!$E$1:$AD$1,0)),5),MROUND(INDEX(df_proj!$E$2:$AD$1000, MATCH(1, ($B$2 = df_proj!$A$2:$A$1000) * (df_proj!$B$2:$B$1000 = $B11) * (df_proj!$C$2:$C$1000 = $D$2), 0), MATCH(TEXT(N$8, "####"), df_proj!$E$1:$AD$1,0)) * popn_fut!$C83/popn_fut!$E83,5))} -> #N/A | O11: {=IFERROR(MROUND(INDEX(df_proj!$E$2:$AD$1000, MATCH(1, ($A$2 = df_proj!$A$2:$A$1000) * (df_proj!$B$2:$B$1000 = $B11) * (df_proj!$C$2:$C$1000 = $D$2), 0), MATCH(TEXT(O$8, "####"), df_proj!$E$1:$AD$1,0)),5),MROUND(INDEX(df_proj!$E$2:$AD$1000, MATCH(1, ($B$2 = df_proj!$A$2:$A$1000) * (df_proj!$B$2:$B$1000 = $B11) * (df_proj!$C$2:$C$1000 = $D$2), 0), MATCH(TEXT(O$8, "####"), df_proj!$E$1:$AD$1,0)) * popn_fut!$C83/popn_fut!$E83,5))} -> #N/A | P11: {=IFERROR(MROUND(INDEX(df_proj!$E$2:$AD$1000, MATCH(1, ($A$2 = df_proj!$A$2:$A$1000) * (df_proj!$B$2:$B$1000 = $B11) * (df_proj!$C$2:$C$1000 = $D$2), 0), MATCH(TEXT(P$8, "####"), df_proj!$E$1:$AD$1,0)),5),MROUND(INDEX(df_proj!$E$2:$AD$1000, MATCH(1, ($B$2 = df_proj!$A$2:$A$1000) * (df_proj!$B$2:$B$1000 = $B11) * (df_proj!$C$2:$C$1000 = $D$2), 0), MATCH(TEXT(P$8, "####"), df_proj!$E$1:$AD$1,0)) * popn_fut!$C83/popn_fut!$E83,5))} -> #N/A | Q11: {=IFERROR(MROUND(INDEX(df_proj!$E$2:$AD$1000, MATCH(1, ($A$2 = df_proj!$A$2:$A$1000) * (df_proj!$B$2:$B$1000 = $B11) * (df_proj!$C$2:$C$1000 = $D$2), 0), MATCH(TEXT(Q$8, "####"), df_proj!$E$1:$AD$1,0)),5),MROUND(INDEX(df_proj!$E$2:$AD$1000, MATCH(1, ($B$2 = df_proj!$A$2:$A$1000) * (df_proj!$B$2:$B$1000 = $B11) * (df_proj!$C$2:$C$1000 = $D$2), 0), MATCH(TEXT(Q$8, "####"), df_proj!$E$1:$AD$1,0)) * popn_fut!$C83/popn_fut!$E83,5))} -> #N/A | R11: {=IFERROR(MROUND(INDEX(df_proj!$E$2:$AD$1000, MATCH(1, ($A$2 = df_proj!$A$2:$A$1000) * (df_proj!$B$2:$B$1000 = $B11) * (df_proj!$C$2:$C$1000 = $D$2), 0), MATCH(TEXT(R$8, "####"), df_proj!$E$1:$AD$1,0)),5),MROUND(INDEX(df_proj!$E$2:$AD$1000, MATCH(1, ($B$2 = df_proj!$A$2:$A$1000) * (df_proj!$B$2:$B$1000 = $B11) * (df_proj!$C$2:$C$1000 = $D$2), 0), MATCH(TEXT(R$8, "####"), df_proj!$E$1:$AD$1,0)) * popn_fut!$C83/popn_fut!$E83,5))} -> #N/A | S11: {=IFERROR(MROUND(INDEX(df_proj!$E$2:$AD$1000, MATCH(1, ($A$2 = df_proj!$A$2:$A$1000) * (df_proj!$B$2:$B$1000 = $B11) * (df_proj!$C$2:$C$1000 = $D$2), 0), MATCH(TEXT(S$8, "####"), df_proj!$E$1:$AD$1,0)),5),MROUND(INDEX(df_proj!$E$2:$AD$1000, MATCH(1, ($B$2 = df_proj!$A$2:$A$1000) * (df_proj!$B$2:$B$1000 = $B11) * (df_proj!$C$2:$C$1000 = $D$2), 0), MATCH(TEXT(S$8, "####"), df_proj!$E$1:$AD$1,0)) * popn_fut!$C83/popn_fut!$E83,5))} -> #N/A | T11: {=IFERROR(MROUND(INDEX(df_proj!$E$2:$AD$1000, MATCH(1, ($A$2 = df_proj!$A$2:$A$1000) * (df_proj!$B$2:$B$1000 = $B11) * (df_proj!$C$2:$C$1000 = $D$2), 0), MATCH(TEXT(T$8, "####"), df_proj!$E$1:$AD$1,0)),5),MROUND(INDEX(df_proj!$E$2:$AD$1000, MATCH(1, ($B$2 = df_proj!$A$2:$A$1000) * (df_proj!$B$2:$B$1000 = $B11) * (df_proj!$C$2:$C$1000 = $D$2), 0), MATCH(TEXT(T$8, "####"), df_proj!$E$1:$AD$1,0)) * popn_fut!$C83/popn_fut!$E83,5))} -> #N/A | ... AL11: {=IFERROR(MROUND(INDEX(df_proj!$E$2:$AD$1000, MATCH(1, ($A$2 = df_proj!$A$2:$A$1000) * (df_proj!$B$2:$B$1000 = $B11) * (df_proj!$C$2:$C$1000 = $D$2), 0), MATCH(TEXT(AL$8, "####"), df_proj!$E$1:$AD$1,0)),5),MROUND(INDEX(df_proj!$E$2:$AD$1000, MATCH(1, ($B$2 = df_proj!$A$2:$A$1000) * (df_proj!$B$2:$B$1000 = $B11) * (df_proj!$C$2:$C$1000 = $D$2), 0), MATCH(TEXT(AL$8, "####"), df_proj!$E$1:$AD$1,0)) * popn_fut!$C83/popn_fut!$E83,5))} -> #N/A | AM11: =AM10+I11 -> #N/A | AP11: =AP10+W11 -> #N/A
A12: 10 | B12: 10 to 14 | D12: #N/A | I12: #N/A | M12: {=IFERROR(MROUND(INDEX(df_proj!$E$2:$AD$1000, MATCH(1, ($A$2 = df_proj!$A$2:$A$1000) * (df_proj!$B$2:$B$1000 = $B12) * (df_proj!$C$2:$C$1000 = $D$2), 0), MATCH(TEXT(M$8, "####"), df_proj!$E$1:$AD$1,0)),5),MROUND(INDEX(df_proj!$E$2:$AD$1000, MATCH(1, ($B$2 = df_proj!$A$2:$A$1000) * (df_proj!$B$2:$B$1000 = $B12) * (df_proj!$C$2:$C$1000 = $D$2), 0), MATCH(TEXT(M$8, "####"), df_proj!$E$1:$AD$1,0)) * popn_fut!$C84/popn_fut!$E84,5))} -> #N/A | N12: {=IFERROR(MROUND(INDEX(df_proj!$E$2:$AD$1000, MATCH(1, ($A$2 = df_proj!$A$2:$A$1000) * (df_proj!$B$2:$B$1000 = $B12) * (df_proj!$C$2:$C$1000 = $D$2), 0), MATCH(TEXT(N$8, "####"), df_proj!$E$1:$AD$1,0)),5),MROUND(INDEX(df_proj!$E$2:$AD$1000, MATCH(1, ($B$2 = df_proj!$A$2:$A$1000) * (df_proj!$B$2:$B$1000 = $B12) * (df_proj!$C$2:$C$1000 = $D$2), 0), MATCH(TEXT(N$8, "####"), df_proj!$E$1:$AD$1,0)) * popn_fut!$C84/popn_fut!$E84,5))} -> #N/A | O12: {=IFERROR(MROUND(INDEX(df_proj!$E$2:$AD$1000, MATCH(1, ($A$2 = df_proj!$A$2:$A$1000) * (df_proj!$B$2:$B$1000 = $B12) * (df_proj!$C$2:$C$1000 = $D$2), 0), MATCH(TEXT(O$8, "####"), df_proj!$E$1:$AD$1,0)),5),MROUND(INDEX(df_proj!$E$2:$AD$1000, MATCH(1, ($B$2 = df_proj!$A$2:$A$1000) * (df_proj!$B$2:$B$1000 = $B12) * (df_proj!$C$2:$C$1000 = $D$2), 0), MATCH(TEXT(O$8, "####"), df_proj!$E$1:$AD$1,0)) * popn_fut!$C84/popn_fut!$E84,5))} -> #N/A | P12: {=IFERROR(MROUND(INDEX(df_proj!$E$2:$AD$1000, MATCH(1, ($A$2 = df_proj!$A$2:$A$1000) * (df_proj!$B$2:$B$1000 = $B12) * (df_proj!$C$2:$C$1000 = $D$2), 0), MATCH(TEXT(P$8, "####"), df_proj!$E$1:$AD$1,0)),5),MROUND(INDEX(df_proj!$E$2:$AD$1000, MATCH(1, ($B$2 = df_proj!$A$2:$A$1000) * (df_proj!$B$2:$B$1000 = $B12) * (df_proj!$C$2:$C$1000 = $D$2), 0), MATCH(TEXT(P$8, "####"), df_proj!$E$1:$AD$1,0)) * popn_fut!$C84/popn_fut!$E84,5))} -> #N/A | Q12: {=IFERROR(MROUND(INDEX(df_proj!$E$2:$AD$1000, MATCH(1, ($A$2 = df_proj!$A$2:$A$1000) * (df_proj!$B$2:$B$1000 = $B12) * (df_proj!$C$2:$C$1000 = $D$2), 0), MATCH(TEXT(Q$8, "####"), df_proj!$E$1:$AD$1,0)),5),MROUND(INDEX(df_proj!$E$2:$AD$1000, MATCH(1, ($B$2 = df_proj!$A$2:$A$1000) * (df_proj!$B$2:$B$1000 = $B12) * (df_proj!$C$2:$C$1000 = $D$2), 0), MATCH(TEXT(Q$8, "####"), df_proj!$E$1:$AD$1,0)) * popn_fut!$C84/popn_fut!$E84,5))} -> #N/A | R12: {=IFERROR(MROUND(INDEX(df_proj!$E$2:$AD$1000, MATCH(1, ($A$2 = df_proj!$A$2:$A$1000) * (df_proj!$B$2:$B$1000 = $B12) * (df_proj!$C$2:$C$1000 = $D$2), 0), MATCH(TEXT(R$8, "####"), df_proj!$E$1:$AD$1,0)),5),MROUND(INDEX(df_proj!$E$2:$AD$1000, MATCH(1, ($B$2 = df_proj!$A$2:$A$1000) * (df_proj!$B$2:$B$1000 = $B12) * (df_proj!$C$2:$C$1000 = $D$2), 0), MATCH(TEXT(R$8, "####"), df_proj!$E$1:$AD$1,0)) * popn_fut!$C84/popn_fut!$E84,5))} -> #N/A | S12: {=IFERROR(MROUND(INDEX(df_proj!$E$2:$AD$1000, MATCH(1, ($A$2 = df_proj!$A$2:$A$1000) * (df_proj!$B$2:$B$1000 = $B12) * (df_proj!$C$2:$C$1000 = $D$2), 0), MATCH(TEXT(S$8, "####"), df_proj!$E$1:$AD$1,0)),5),MROUND(INDEX(df_proj!$E$2:$AD$1000, MATCH(1, ($B$2 = df_proj!$A$2:$A$1000) * (df_proj!$B$2:$B$1000 = $B12) * (df_proj!$C$2:$C$1000 = $D$2), 0), MATCH(TEXT(S$8, "####"), df_proj!$E$1:$AD$1,0)) * popn_fut!$C84/popn_fut!$E84,5))} -> #N/A | T12: {=IFERROR(MROUND(INDEX(df_proj!$E$2:$AD$1000, MATCH(1, ($A$2 = df_proj!$A$2:$A$1000) * (df_proj!$B$2:$B$1000 = $B12) * (df_proj!$C$2:$C$1000 = $D$2), 0), MATCH(TEXT(T$8, "####"), df_proj!$E$1:$AD$1,0)),5),MROUND(INDEX(df_proj!$E$2:$AD$1000, MATCH(1, ($B$2 = df_proj!$A$2:$A$1000) * (df_proj!$B$2:$B$1000 = $B12) * (df_proj!$C$2:$C$1000 = $D$2), 0), MATCH(TEXT(T$8, "####"), df_proj!$E$1:$AD$1,0)) * popn_fut!$C84/popn_fut!$E84,5))} -> #N/A | ... AL12: {=IFERROR(MROUND(INDEX(df_proj!$E$2:$AD$1000, MATCH(1, ($A$2 = df_proj!$A$2:$A$1000) * (df_proj!$B$2:$B$1000 = $B12) * (df_proj!$C$2:$C$1000 = $D$2), 0), MATCH(TEXT(AL$8, "####"), df_proj!$E$1:$AD$1,0)),5),MROUND(INDEX(df_proj!$E$2:$AD$1000, MATCH(1, ($B$2 = df_proj!$A$2:$A$1000) * (df_proj!$B$2:$B$1000 = $B12) * (df_proj!$C$2:$C$1000 = $D$2), 0), MATCH(TEXT(AL$8, "####"), df_proj!$E$1:$AD$1,0)) * popn_fut!$C84/popn_fut!$E84,5))} -> #N/A | AM12: =AM11+I12 -> #N/A | AP12: =AP11+W12 -> #N/A
A13: 15 | B13: 15 to 19 | D13: #N/A | I13: #N/A | M13: {=IFERROR(MROUND(INDEX(df_proj!$E$2:$AD$1000, MATCH(1, ($A$2 = df_proj!$A$2:$A$1000) * (df_proj!$B$2:$B$1000 = $B13) * (df_proj!$C$2:$C$1000 = $D$2), 0), MATCH(TEXT(M$8, "####"), df_proj!$E$1:$AD$1,0)),5),MROUND(INDEX(df_proj!$E$2:$AD$1000, MATCH(1, ($B$2 = df_proj!$A$2:$A$1000) * (df_proj!$B$2:$B$1000 = $B13) * (df_proj!$C$2:$C$1000 = $D$2), 0), MATCH(TEXT(M$8, "####"), df_proj!$E$1:$AD$1,0)) * popn_fut!$C85/popn_fut!$E85,5))} -> #N/A | N13: {=IFERROR(MROUND(INDEX(df_proj!$E$2:$AD$1000, MATCH(1, ($A$2 = df_proj!$A$2:$A$1000) * (df_proj!$B$2:$B$1000 = $B13) * (df_proj!$C$2:$C$1000 = $D$2), 0), MATCH(TEXT(N$8, "####"), df_proj!$E$1:$AD$1,0)),5),MROUND(INDEX(df_proj!$E$2:$AD$1000, MATCH(1, ($B$2 = df_proj!$A$2:$A$1000) * (df_proj!$B$2:$B$1000 = $B13) * (df_proj!$C$2:$C$1000 = $D$2), 0), MATCH(TEXT(N$8, "####"), df_proj!$E$1:$AD$1,0)) * popn_fut!$C85/popn_fut!$E85,5))} -> #N/A | O13: {=IFERROR(MROUND(INDEX(df_proj!$E$2:$AD$1000, MATCH(1, ($A$2 = df_proj!$A$2:$A$1000) * (df_proj!$B$2:$B$1000 = $B13) * (df_proj!$C$2:$C$1000 = $D$2), 0), MATCH(TEXT(O$8, "####"), df_proj!$E$1:$AD$1,0)),5),MROUND(INDEX(df_proj!$E$2:$AD$1000, MATCH(1, ($B$2 = df_proj!$A$2:$A$1000) * (df_proj!$B$2:$B$1000 = $B13) * (df_proj!$C$2:$C$1000 = $D$2), 0), MATCH(TEXT(O$8, "####"), df_proj!$E$1:$AD$1,0)) * popn_fut!$C85/popn_fut!$E85,5))} -> #N/A | P13: {=IFERROR(MROUND(INDEX(df_proj!$E$2:$AD$1000, MATCH(1, ($A$2 = df_proj!$A$2:$A$1000) * (df_proj!$B$2:$B$1000 = $B13) * (df_proj!$C$2:$C$1000 = $D$2), 0), MATCH(TEXT(P$8, "####"), df_proj!$E$1:$AD$1,0)),5),MROUND(INDEX(df_proj!$E$2:$AD$1000, MATCH(1, ($B$2 = df_proj!$A$2:$A$1000) * (df_proj!$B$2:$B$1000 = $B13) * (df_proj!$C$2:$C$1000 = $D$2), 0), MATCH(TEXT(P$8, "####"), df_proj!$E$1:$AD$1,0)) * popn_fut!$C85/popn_fut!$E85,5))} -> #N/A | Q13: {=IFERROR(MROUND(INDEX(df_proj!$E$2:$AD$1000, MATCH(1, ($A$2 = df_proj!$A$2:$A$1000) * (df_proj!$B$2:$B$1000 = $B13) * (df_proj!$C$2:$C$1000 = $D$2), 0), MATCH(TEXT(Q$8, "####"), df_proj!$E$1:$AD$1,0)),5),MROUND(INDEX(df_proj!$E$2:$AD$1000, MATCH(1, ($B$2 = df_proj!$A$2:$A$1000) * (df_proj!$B$2:$B$1000 = $B13) * (df_proj!$C$2:$C$1000 = $D$2), 0), MATCH(TEXT(Q$8, "####"), df_proj!$E$1:$AD$1,0)) * popn_fut!$C85/popn_fut!$E85,5))} -> #N/A | R13: {=IFERROR(MROUND(INDEX(df_proj!$E$2:$AD$1000, MATCH(1, ($A$2 = df_proj!$A$2:$A$1000) * (df_proj!$B$2:$B$1000 = $B13) * (df_proj!$C$2:$C$1000 = $D$2), 0), MATCH(TEXT(R$8, "####"), df_proj!$E$1:$AD$1,0)),5),MROUND(INDEX(df_proj!$E$2:$AD$1000, MATCH(1, ($B$2 = df_proj!$A$2:$A$1000) * (df_proj!$B$2:$B$1000 = $B13) * (df_proj!$C$2:$C$1000 = $D$2), 0), MATCH(TEXT(R$8, "####"), df_proj!$E$1:$AD$1,0)) * popn_fut!$C85/popn_fut!$E85,5))} -> #N/A | S13: {=IFERROR(MROUND(INDEX(df_proj!$E$2:$AD$1000, MATCH(1, ($A$2 = df_proj!$A$2:$A$1000) * (df_proj!$B$2:$B$1000 = $B13) * (df_proj!$C$2:$C$1000 = $D$2), 0), MATCH(TEXT(S$8, "####"), df_proj!$E$1:$AD$1,0)),5),MROUND(INDEX(df_proj!$E$2:$AD$1000, MATCH(1, ($B$2 = df_proj!$A$2:$A$1000) * (df_proj!$B$2:$B$1000 = $B13) * (df_proj!$C$2:$C$1000 = $D$2), 0), MATCH(TEXT(S$8, "####"), df_proj!$E$1:$AD$1,0)) * popn_fut!$C85/popn_fut!$E85,5))} -> #N/A | T13: {=IFERROR(MROUND(INDEX(df_proj!$E$2:$AD$1000, MATCH(1, ($A$2 = df_proj!$A$2:$A$1000) * (df_proj!$B$2:$B$1000 = $B13) * (df_proj!$C$2:$C$1000 = $D$2), 0), MATCH(TEXT(T$8, "####"), df_proj!$E$1:$AD$1,0)),5),MROUND(INDEX(df_proj!$E$2:$AD$1000, MATCH(1, ($B$2 = df_proj!$A$2:$A$1000) * (df_proj!$B$2:$B$1000 = $B13) * (df_proj!$C$2:$C$1000 = $D$2), 0), MATCH(TEXT(T$8, "####"), df_proj!$E$1:$AD$1,0)) * popn_fut!$C85/popn_fut!$E85,5))} -> #N/A | ... AL13: {=IFERROR(MROUND(INDEX(df_proj!$E$2:$AD$1000, MATCH(1, ($A$2 = df_proj!$A$2:$A$1000) * (df_proj!$B$2:$B$1000 = $B13) * (df_proj!$C$2:$C$1000 = $D$2), 0), MATCH(TEXT(AL$8, "####"), df_proj!$E$1:$AD$1,0)),5),MROUND(INDEX(df_proj!$E$2:$AD$1000, MATCH(1, ($B$2 = df_proj!$A$2:$A$1000) * (df_proj!$B$2:$B$1000 = $B13) * (df_proj!$C$2:$C$1000 = $D$2), 0), MATCH(TEXT(AL$8, "####"), df_proj!$E$1:$AD$1,0)) * popn_fut!$C85/popn_fut!$E85,5))} -> #N/A | AM13: =AM12+I13 -> #N/A | AP13: =AP12+W13 -> #N/A
A14: 20 | B14: 20 to 24 | D14: #N/A | I14: #N/A | M14: {=IFERROR(MROUND(INDEX(df_proj!$E$2:$AD$1000, MATCH(1, ($A$2 = df_proj!$A$2:$A$1000) * (df_proj!$B$2:$B$1000 = $B14) * (df_proj!$C$2:$C$1000 = $D$2), 0), MATCH(TEXT(M$8, "####"), df_proj!$E$1:$AD$1,0)),5),MROUND(INDEX(df_proj!$E$2:$AD$1000, MATCH(1, ($B$2 = df_proj!$A$2:$A$1000) * (df_proj!$B$2:$B$1000 = $B14) * (df_proj!$C$2:$C$1000 = $D$2), 0), MATCH(TEXT(M$8, "####"), df_proj!$E$1:$AD$1,0)) * popn_fut!$C86/popn_fut!$E86,5))} -> #N/A | N14: {=IFERROR(MROUND(INDEX(df_proj!$E$2:$AD$1000, MATCH(1, ($A$2 = df_proj!$A$2:$A$1000) * (df_proj!$B$2:$B$1000 = $B14) * (df_proj!$C$2:$C$1000 = $D$2), 0), MATCH(TEXT(N$8, "####"), df_proj!$E$1:$AD$1,0)),5),MROUND(INDEX(df_proj!$E$2:$AD$1000, MATCH(1, ($B$2 = df_proj!$A$2:$A$1000) * (df_proj!$B$2:$B$1000 = $B14) * (df_proj!$C$2:$C$1000 = $D$2), 0), MATCH(TEXT(N$8, "####"), df_proj!$E$1:$AD$1,0)) * popn_fut!$C86/popn_fut!$E86,5))} -> #N/A | O14: {=IFERROR(MROUND(INDEX(df_proj!$E$2:$AD$1000, MATCH(1, ($A$2 = df_proj!$A$2:$A$1000) * (df_proj!$B$2:$B$1000 = $B14) * (df_proj!$C$2:$C$1000 = $D$2), 0), MATCH(TEXT(O$8, "####"), df_proj!$E$1:$AD$1,0)),5),MROUND(INDEX(df_proj!$E$2:$AD$1000, MATCH(1, ($B$2 = df_proj!$A$2:$A$1000) * (df_proj!$B$2:$B$1000 = $B14) * (df_proj!$C$2:$C$1000 = $D$2), 0), MATCH(TEXT(O$8, "####"), df_proj!$E$1:$AD$1,0)) * popn_fut!$C86/popn_fut!$E86,5))} -> #N/A | P14: {=IFERROR(MROUND(INDEX(df_proj!$E$2:$AD$1000, MATCH(1, ($A$2 = df_proj!$A$2:$A$1000) * (df_proj!$B$2:$B$1000 = $B14) * (df_proj!$C$2:$C$1000 = $D$2), 0), MATCH(TEXT(P$8, "####"), df_proj!$E$1:$AD$1,0)),5),MROUND(INDEX(df_proj!$E$2:$AD$1000, MATCH(1, ($B$2 = df_proj!$A$2:$A$1000) * (df_proj!$B$2:$B$1000 = $B14) * (df_proj!$C$2:$C$1000 = $D$2), 0), MATCH(TEXT(P$8, "####"), df_proj!$E$1:$AD$1,0)) * popn_fut!$C86/popn_fut!$E86,5))} -> #N/A | Q14: {=IFERROR(MROUND(INDEX(df_proj!$E$2:$AD$1000, MATCH(1, ($A$2 = df_proj!$A$2:$A$1000) * (df_proj!$B$2:$B$1000 = $B14) * (df_proj!$C$2:$C$1000 = $D$2), 0), MATCH(TEXT(Q$8, "####"), df_proj!$E$1:$AD$1,0)),5),MROUND(INDEX(df_proj!$E$2:$AD$1000, MATCH(1, ($B$2 = df_proj!$A$2:$A$1000) * (df_proj!$B$2:$B$1000 = $B14) * (df_proj!$C$2:$C$1000 = $D$2), 0), MATCH(TEXT(Q$8, "####"), df_proj!$E$1:$AD$1,0)) * popn_fut!$C86/popn_fut!$E86,5))} -> #N/A | R14: {=IFERROR(MROUND(INDEX(df_proj!$E$2:$AD$1000, MATCH(1, ($A$2 = df_proj!$A$2:$A$1000) * (df_proj!$B$2:$B$1000 = $B14) * (df_proj!$C$2:$C$1000 = $D$2), 0), MATCH(TEXT(R$8, "####"), df_proj!$E$1:$AD$1,0)),5),MROUND(INDEX(df_proj!$E$2:$AD$1000, MATCH(1, ($B$2 = df_proj!$A$2:$A$1000) * (df_proj!$B$2:$B$1000 = $B14) * (df_proj!$C$2:$C$1000 = $D$2), 0), MATCH(TEXT(R$8, "####"), df_proj!$E$1:$AD$1,0)) * popn_fut!$C86/popn_fut!$E86,5))} -> #N/A | S14: {=IFERROR(MROUND(INDEX(df_proj!$E$2:$AD$1000, MATCH(1, ($A$2 = df_proj!$A$2:$A$1000) * (df_proj!$B$2:$B$1000 = $B14) * (df_proj!$C$2:$C$1000 = $D$2), 0), MATCH(TEXT(S$8, "####"), df_proj!$E$1:$AD$1,0)),5),MROUND(INDEX(df_proj!$E$2:$AD$1000, MATCH(1, ($B$2 = df_proj!$A$2:$A$1000) * (df_proj!$B$2:$B$1000 = $B14) * (df_proj!$C$2:$C$1000 = $D$2), 0), MATCH(TEXT(S$8, "####"), df_proj!$E$1:$AD$1,0)) * popn_fut!$C86/popn_fut!$E86,5))} -> #N/A | T14: {=IFERROR(MROUND(INDEX(df_proj!$E$2:$AD$1000, MATCH(1, ($A$2 = df_proj!$A$2:$A$1000) * (df_proj!$B$2:$B$1000 = $B14) * (df_proj!$C$2:$C$1000 = $D$2), 0), MATCH(TEXT(T$8, "####"), df_proj!$E$1:$AD$1,0)),5),MROUND(INDEX(df_proj!$E$2:$AD$1000, MATCH(1, ($B$2 = df_proj!$A$2:$A$1000) * (df_proj!$B$2:$B$1000 = $B14) * (df_proj!$C$2:$C$1000 = $D$2), 0), MATCH(TEXT(T$8, "####"), df_proj!$E$1:$AD$1,0)) * popn_fut!$C86/popn_fut!$E86,5))} -> #N/A | ... AL14: {=IFERROR(MROUND(INDEX(df_proj!$E$2:$AD$1000, MATCH(1, ($A$2 = df_proj!$A$2:$A$1000) * (df_proj!$B$2:$B$1000 = $B14) * (df_proj!$C$2:$C$1000 = $D$2), 0), MATCH(TEXT(AL$8, "####"), df_proj!$E$1:$AD$1,0)),5),MROUND(INDEX(df_proj!$E$2:$AD$1000, MATCH(1, ($B$2 = df_proj!$A$2:$A$1000) * (df_proj!$B$2:$B$1000 = $B14) * (df_proj!$C$2:$C$1000 = $D$2), 0), MATCH(TEXT(AL$8, "####"), df_proj!$E$1:$AD$1,0)) * popn_fut!$C86/popn_fut!$E86,5))} -> #N/A | AM14: =AM13+I14 -> #N/A | AP14: =AP13+W14 -> #N/A
A15: 25 | B15: 25 to 29 | D15: #N/A | I15: #N/A | M15: {=IFERROR(MROUND(INDEX(df_proj!$E$2:$AD$1000, MATCH(1, ($A$2 = df_proj!$A$2:$A$1000) * (df_proj!$B$2:$B$1000 = $B15) * (df_proj!$C$2:$C$1000 = $D$2), 0), MATCH(TEXT(M$8, "####"), df_proj!$E$1:$AD$1,0)),5),MROUND(INDEX(df_proj!$E$2:$AD$1000, MATCH(1, ($B$2 = df_proj!$A$2:$A$1000) * (df_proj!$B$2:$B$1000 = $B15) * (df_proj!$C$2:$C$1000 = $D$2), 0), MATCH(TEXT(M$8, "####"), df_proj!$E$1:$AD$1,0)) * popn_fut!$C87/popn_fut!$E87,5))} -> #N/A | N15: {=IFERROR(MROUND(INDEX(df_proj!$E$2:$AD$1000, MATCH(1, ($A$2 = df_proj!$A$2:$A$1000) * (df_proj!$B$2:$B$1000 = $B15) * (df_proj!$C$2:$C$1000 = $D$2), 0), MATCH(TEXT(N$8, "####"), df_proj!$E$1:$AD$1,0)),5),MROUND(INDEX(df_proj!$E$2:$AD$1000, MATCH(1, ($B$2 = df_proj!$A$2:$A$1000) * (df_proj!$B$2:$B$1000 = $B15) * (df_proj!$C$2:$C$1000 = $D$2), 0), MATCH(TEXT(N$8, "####"), df_proj!$E$1:$AD$1,0)) * popn_fut!$C87/popn_fut!$E87,5))} -> #N/A | O15: {=IFERROR(MROUND(INDEX(df_proj!$E$2:$AD$1000, MATCH(1, ($A$2 = df_proj!$A$2:$A$1000) * (df_proj!$B$2:$B$1000 = $B15) * (df_proj!$C$2:$C$1000 = $D$2), 0), MATCH(TEXT(O$8, "####"), df_proj!$E$1:$AD$1,0)),5),MROUND(INDEX(df_proj!$E$2:$AD$1000, MATCH(1, ($B$2 = df_proj!$A$2:$A$1000) * (df_proj!$B$2:$B$1000 = $B15) * (df_proj!$C$2:$C$1000 = $D$2), 0), MATCH(TEXT(O$8, "####"), df_proj!$E$1:$AD$1,0)) * popn_fut!$C87/popn_fut!$E87,5))} -> #N/A | P15: {=IFERROR(MROUND(INDEX(df_proj!$E$2:$AD$1000, MATCH(1, ($A$2 = df_proj!$A$2:$A$1000) * (df_proj!$B$2:$B$1000 = $B15) * (df_proj!$C$2:$C$1000 = $D$2), 0), MATCH(TEXT(P$8, "####"), df_proj!$E$1:$AD$1,0)),5),MROUND(INDEX(df_proj!$E$2:$AD$1000, MATCH(1, ($B$2 = df_proj!$A$2:$A$1000) * (df_proj!$B$2:$B$1000 = $B15) * (df_proj!$C$2:$C$1000 = $D$2), 0), MATCH(TEXT(P$8, "####"), df_proj!$E$1:$AD$1,0)) * popn_fut!$C87/popn_fut!$E87,5))} -> #N/A | Q15: {=IFERROR(MROUND(INDEX(df_proj!$E$2:$AD$1000, MATCH(1, ($A$2 = df_proj!$A$2:$A$1000) * (df_proj!$B$2:$B$1000 = $B15) * (df_proj!$C$2:$C$1000 = $D$2), 0), MATCH(TEXT(Q$8, "####"), df_proj!$E$1:$AD$1,0)),5),MROUND(INDEX(df_proj!$E$2:$AD$1000, MATCH(1, ($B$2 = df_proj!$A$2:$A$1000) * (df_proj!$B$2:$B$1000 = $B15) * (df_proj!$C$2:$C$1000 = $D$2), 0), MATCH(TEXT(Q$8, "####"), df_proj!$E$1:$AD$1,0)) * popn_fut!$C87/popn_fut!$E87,5))} -> #N/A | R15: {=IFERROR(MROUND(INDEX(df_proj!$E$2:$AD$1000, MATCH(1, ($A$2 = df_proj!$A$2:$A$1000) * (df_proj!$B$2:$B$1000 = $B15) * (df_proj!$C$2:$C$1000 = $D$2), 0), MATCH(TEXT(R$8, "####"), df_proj!$E$1:$AD$1,0)),5),MROUND(INDEX(df_proj!$E$2:$AD$1000, MATCH(1, ($B$2 = df_proj!$A$2:$A$1000) * (df_proj!$B$2:$B$1000 = $B15) * (df_proj!$C$2:$C$1000 = $D$2), 0), MATCH(TEXT(R$8, "####"), df_proj!$E$1:$AD$1,0)) * popn_fut!$C87/popn_fut!$E87,5))} -> #N/A | S15: {=IFERROR(MROUND(INDEX(df_proj!$E$2:$AD$1000, MATCH(1, ($A$2 = df_proj!$A$2:$A$1000) * (df_proj!$B$2:$B$1000 = $B15) * (df_proj!$C$2:$C$1000 = $D$2), 0), MATCH(TEXT(S$8, "####"), df_proj!$E$1:$AD$1,0)),5),MROUND(INDEX(df_proj!$E$2:$AD$1000, MATCH(1, ($B$2 = df_proj!$A$2:$A$1000) * (df_proj!$B$2:$B$1000 = $B15) * (df_proj!$C$2:$C$1000 = $D$2), 0), MATCH(TEXT(S$8, "####"), df_proj!$E$1:$AD$1,0)) * popn_fut!$C87/popn_fut!$E87,5))} -> #N/A | T15: {=IFERROR(MROUND(INDEX(df_proj!$E$2:$AD$1000, MATCH(1, ($A$2 = df_proj!$A$2:$A$1000) * (df_proj!$B$2:$B$1000 = $B15) * (df_proj!$C$2:$C$1000 = $D$2), 0), MATCH(TEXT(T$8, "####"), df_proj!$E$1:$AD$1,0)),5),MROUND(INDEX(df_proj!$E$2:$AD$1000, MATCH(1, ($B$2 = df_proj!$A$2:$A$1000) * (df_proj!$B$2:$B$1000 = $B15) * (df_proj!$C$2:$C$1000 = $D$2), 0), MATCH(TEXT(T$8, "####"), df_proj!$E$1:$AD$1,0)) * popn_fut!$C87/popn_fut!$E87,5))} -> #N/A | ... AL15: {=IFERROR(MROUND(INDEX(df_proj!$E$2:$AD$1000, MATCH(1, ($A$2 = df_proj!$A$2:$A$1000) * (df_proj!$B$2:$B$1000 = $B15) * (df_proj!$C$2:$C$1000 = $D$2), 0), MATCH(TEXT(AL$8, "####"), df_proj!$E$1:$AD$1,0)),5),MROUND(INDEX(df_proj!$E$2:$AD$1000, MATCH(1, ($B$2 = df_proj!$A$2:$A$1000) * (df_proj!$B$2:$B$1000 = $B15) * (df_proj!$C$2:$C$1000 = $D$2), 0), MATCH(TEXT(AL$8, "####"), df_proj!$E$1:$AD$1,0)) * popn_fut!$C87/popn_fut!$E87,5))} -> #N/A | AM15: =AM14+I15 -> #N/A | AP15: =AP14+W15 -> #N/A
A16: 30 | B16: 30 to 34 | D16: #N/A | I16: #N/A | M16: {=IFERROR(MROUND(INDEX(df_proj!$E$2:$AD$1000, MATCH(1, ($A$2 = df_proj!$A$2:$A$1000) * (df_proj!$B$2:$B$1000 = $B16) * (df_proj!$C$2:$C$1000 = $D$2), 0), MATCH(TEXT(M$8, "####"), df_proj!$E$1:$AD$1,0)),5),MROUND(INDEX(df_proj!$E$2:$AD$1000, MATCH(1, ($B$2 = df_proj!$A$2:$A$1000) * (df_proj!$B$2:$B$1000 = $B16) * (df_proj!$C$2:$C$1000 = $D$2), 0), MATCH(TEXT(M$8, "####"), df_proj!$E$1:$AD$1,0)) * popn_fut!$C88/popn_fut!$E88,5))} -> #N/A | N16: {=IFERROR(MROUND(INDEX(df_proj!$E$2:$AD$1000, MATCH(1, ($A$2 = df_proj!$A$2:$A$1000) * (df_proj!$B$2:$B$1000 = $B16) * (df_proj!$C$2:$C$1000 = $D$2), 0), MATCH(TEXT(N$8, "####"), df_proj!$E$1:$AD$1,0)),5),MROUND(INDEX(df_proj!$E$2:$AD$1000, MATCH(1, ($B$2 = df_proj!$A$2:$A$1000) * (df_proj!$B$2:$B$1000 = $B16) * (df_proj!$C$2:$C$1000 = $D$2), 0), MATCH(TEXT(N$8, "####"), df_proj!$E$1:$AD$1,0)) * popn_fut!$C88/popn_fut!$E88,5))} -> #N/A | O16: {=IFERROR(MROUND(INDEX(df_proj!$E$2:$AD$1000, MATCH(1, ($A$2 = df_proj!$A$2:$A$1000) * (df_proj!$B$2:$B$1000 = $B16) * (df_proj!$C$2:$C$1000 = $D$2), 0), MATCH(TEXT(O$8, "####"), df_proj!$E$1:$AD$1,0)),5),MROUND(INDEX(df_proj!$E$2:$AD$1000, MATCH(1, ($B$2 = df_proj!$A$2:$A$1000) * (df_proj!$B$2:$B$1000 = $B16) * (df_proj!$C$2:$C$1000 = $D$2), 0), MATCH(TEXT(O$8, "####"), df_proj!$E$1:$AD$1,0)) * popn_fut!$C88/popn_fut!$E88,5))} -> #N/A | P16: {=IFERROR(MROUND(INDEX(df_proj!$E$2:$AD$1000, MATCH(1, ($A$2 = df_proj!$A$2:$A$1000) * (df_proj!$B$2:$B$1000 = $B16) * (df_proj!$C$2:$C$1000 = $D$2), 0), MATCH(TEXT(P$8, "####"), df_proj!$E$1:$AD$1,0)),5),MROUND(INDEX(df_proj!$E$2:$AD$1000, MATCH(1, ($B$2 = df_proj!$A$2:$A$1000) * (df_proj!$B$2:$B$1000 = $B16) * (df_proj!$C$2:$C$1000 = $D$2), 0), MATCH(TEXT(P$8, "####"), df_proj!$E$1:$AD$1,0)) * popn_fut!$C88/popn_fut!$E88,5))} -> #N/A | Q16: {=IFERROR(MROUND(INDEX(df_proj!$E$2:$AD$1000, MATCH(1, ($A$2 = df_proj!$A$2:$A$1000) * (df_proj!$B$2:$B$1000 = $B16) * (df_proj!$C$2:$C$1000 = $D$2), 0), MATCH(TEXT(Q$8, "####"), df_proj!$E$1:$AD$1,0)),5),MROUND(INDEX(df_proj!$E$2:$AD$1000, MATCH(1, ($B$2 = df_proj!$A$2:$A$1000) * (df_proj!$B$2:$B$1000 = $B16) * (df_proj!$C$2:$C$1000 = $D$2), 0), MATCH(TEXT(Q$8, "####"), df_proj!$E$1:$AD$1,0)) * popn_fut!$C88/popn_fut!$E88,5))} -> #N/A | R16: {=IFERROR(MROUND(INDEX(df_proj!$E$2:$AD$1000, MATCH(1, ($A$2 = df_proj!$A$2:$A$1000) * (df_proj!$B$2:$B$1000 = $B16) * (df_proj!$C$2:$C$1000 = $D$2), 0), MATCH(TEXT(R$8, "####"), df_proj!$E$1:$AD$1,0)),5),MROUND(INDEX(df_proj!$E$2:$AD$1000, MATCH(1, ($B$2 = df_proj!$A$2:$A$1000) * (df_proj!$B$2:$B$1000 = $B16) * (df_proj!$C$2:$C$1000 = $D$2), 0), MATCH(TEXT(R$8, "####"), df_proj!$E$1:$AD$1,0)) * popn_fut!$C88/popn_fut!$E88,5))} -> #N/A | S16: {=IFERROR(MROUND(INDEX(df_proj!$E$2:$AD$1000, MATCH(1, ($A$2 = df_proj!$A$2:$A$1000) * (df_proj!$B$2:$B$1000 = $B16) * (df_proj!$C$2:$C$1000 = $D$2), 0), MATCH(TEXT(S$8, "####"), df_proj!$E$1:$AD$1,0)),5),MROUND(INDEX(df_proj!$E$2:$AD$1000, MATCH(1, ($B$2 = df_proj!$A$2:$A$1000) * (df_proj!$B$2:$B$1000 = $B16) * (df_proj!$C$2:$C$1000 = $D$2), 0), MATCH(TEXT(S$8, "####"), df_proj!$E$1:$AD$1,0)) * popn_fut!$C88/popn_fut!$E88,5))} -> #N/A | T16: {=IFERROR(MROUND(INDEX(df_proj!$E$2:$AD$1000, MATCH(1, ($A$2 = df_proj!$A$2:$A$1000) * (df_proj!$B$2:$B$1000 = $B16) * (df_proj!$C$2:$C$1000 = $D$2), 0), MATCH(TEXT(T$8, "####"), df_proj!$E$1:$AD$1,0)),5),MROUND(INDEX(df_proj!$E$2:$AD$1000, MATCH(1, ($B$2 = df_proj!$A$2:$A$1000) * (df_proj!$B$2:$B$1000 = $B16) * (df_proj!$C$2:$C$1000 = $D$2), 0), MATCH(TEXT(T$8, "####"), df_proj!$E$1:$AD$1,0)) * popn_fut!$C88/popn_fut!$E88,5))} -> #N/A | ... AL16: {=IFERROR(MROUND(INDEX(df_proj!$E$2:$AD$1000, MATCH(1, ($A$2 = df_proj!$A$2:$A$1000) * (df_proj!$B$2:$B$1000 = $B16) * (df_proj!$C$2:$C$1000 = $D$2), 0), MATCH(TEXT(AL$8, "####"), df_proj!$E$1:$AD$1,0)),5),MROUND(INDEX(df_proj!$E$2:$AD$1000, MATCH(1, ($B$2 = df_proj!$A$2:$A$1000) * (df_proj!$B$2:$B$1000 = $B16) * (df_proj!$C$2:$C$1000 = $D$2), 0), MATCH(TEXT(AL$8, "####"), df_proj!$E$1:$AD$1,0)) * popn_fut!$C88/popn_fut!$E88,5))} -> #N/A | AM16: =AM15+I16 -> #N/A | AP16: =AP15+W16 -> #N/A
A17: 35 | B17: 35 to 39 | D17: #N/A | I17: #N/A | M17: {=IFERROR(MROUND(INDEX(df_proj!$E$2:$AD$1000, MATCH(1, ($A$2 = df_proj!$A$2:$A$1000) * (df_proj!$B$2:$B$1000 = $B17) * (df_proj!$C$2:$C$1000 = $D$2), 0), MATCH(TEXT(M$8, "####"), df_proj!$E$1:$AD$1,0)),5),MROUND(INDEX(df_proj!$E$2:$AD$1000, MATCH(1, ($B$2 = df_proj!$A$2:$A$1000) * (df_proj!$B$2:$B$1000 = $B17) * (df_proj!$C$2:$C$1000 = $D$2), 0), MATCH(TEXT(M$8, "####"), df_proj!$E$1:$AD$1,0)) * popn_fut!$C89/popn_fut!$E89,5))} -> #N/A | N17: {=IFERROR(MROUND(INDEX(df_proj!$E$2:$AD$1000, MATCH(1, ($A$2 = df_proj!$A$2:$A$1000) * (df_proj!$B$2:$B$1000 = $B17) * (df_proj!$C$2:$C$1000 = $D$2), 0), MATCH(TEXT(N$8, "####"), df_proj!$E$1:$AD$1,0)),5),MROUND(INDEX(df_proj!$E$2:$AD$1000, MATCH(1, ($B$2 = df_proj!$A$2:$A$1000) * (df_proj!$B$2:$B$1000 = $B17) * (df_proj!$C$2:$C$1000 = $D$2), 0), MATCH(TEXT(N$8, "####"), df_proj!$E$1:$AD$1,0)) * popn_fut!$C89/popn_fut!$E89,5))} -> #N/A | O17: {=IFERROR(MROUND(INDEX(df_proj!$E$2:$AD$1000, MATCH(1, ($A$2 = df_proj!$A$2:$A$1000) * (df_proj!$B$2:$B$1000 = $B17) * (df_proj!$C$2:$C$1000 = $D$2), 0), MATCH(TEXT(O$8, "####"), df_proj!$E$1:$AD$1,0)),5),MROUND(INDEX(df_proj!$E$2:$AD$1000, MATCH(1, ($B$2 = df_proj!$A$2:$A$1000) * (df_proj!$B$2:$B$1000 = $B17) * (df_proj!$C$2:$C$1000 = $D$2), 0), MATCH(TEXT(O$8, "####"), df_proj!$E$1:$AD$1,0)) * popn_fut!$C89/popn_fut!$E89,5))} -> #N/A | P17: {=IFERROR(MROUND(INDEX(df_proj!$E$2:$AD$1000, MATCH(1, ($A$2 = df_proj!$A$2:$A$1000) * (df_proj!$B$2:$B$1000 = $B17) * (df_proj!$C$2:$C$1000 = $D$2), 0), MATCH(TEXT(P$8, "####"), df_proj!$E$1:$AD$1,0)),5),MROUND(INDEX(df_proj!$E$2:$AD$1000, MATCH(1, ($B$2 = df_proj!$A$2:$A$1000) * (df_proj!$B$2:$B$1000 = $B17) * (df_proj!$C$2:$C$1000 = $D$2), 0), MATCH(TEXT(P$8, "####"), df_proj!$E$1:$AD$1,0)) * popn_fut!$C89/popn_fut!$E89,5))} -> #N/A | Q17: {=IFERROR(MROUND(INDEX(df_proj!$E$2:$AD$1000, MATCH(1, ($A$2 = df_proj!$A$2:$A$1000) * (df_proj!$B$2:$B$1000 = $B17) * (df_proj!$C$2:$C$1000 = $D$2), 0), MATCH(TEXT(Q$8, "####"), df_proj!$E$1:$AD$1,0)),5),MROUND(INDEX(df_proj!$E$2:$AD$1000, MATCH(1, ($B$2 = df_proj!$A$2:$A$1000) * (df_proj!$B$2:$B$1000 = $B17) * (df_proj!$C$2:$C$1000 = $D$2), 0), MATCH(TEXT(Q$8, "####"), df_proj!$E$1:$AD$1,0)) * popn_fut!$C89/popn_fut!$E89,5))} -> #N/A | R17: {=IFERROR(MROUND(INDEX(df_proj!$E$2:$AD$1000, MATCH(1, ($A$2 = df_proj!$A$2:$A$1000) * (df_proj!$B$2:$B$1000 = $B17) * (df_proj!$C$2:$C$1000 = $D$2), 0), MATCH(TEXT(R$8, "####"), df_proj!$E$1:$AD$1,0)),5),MROUND(INDEX(df_proj!$E$2:$AD$1000, MATCH(1, ($B$2 = df_proj!$A$2:$A$1000) * (df_proj!$B$2:$B$1000 = $B17) * (df_proj!$C$2:$C$1000 = $D$2), 0), MATCH(TEXT(R$8, "####"), df_proj!$E$1:$AD$1,0)) * popn_fut!$C89/popn_fut!$E89,5))} -> #N/A | S17: {=IFERROR(MROUND(INDEX(df_proj!$E$2:$AD$1000, MATCH(1, ($A$2 = df_proj!$A$2:$A$1000) * (df_proj!$B$2:$B$1000 = $B17) * (df_proj!$C$2:$C$1000 = $D$2), 0), MATCH(TEXT(S$8, "####"), df_proj!$E$1:$AD$1,0)),5),MROUND(INDEX(df_proj!$E$2:$AD$1000, MATCH(1, ($B$2 = df_proj!$A$2:$A$1000) * (df_proj!$B$2:$B$1000 = $B17) * (df_proj!$C$2:$C$1000 = $D$2), 0), MATCH(TEXT(S$8, "####"), df_proj!$E$1:$AD$1,0)) * popn_fut!$C89/popn_fut!$E89,5))} -> #N/A | T17: {=IFERROR(MROUND(INDEX(df_proj!$E$2:$AD$1000, MATCH(1, ($A$2 = df_proj!$A$2:$A$1000) * (df_proj!$B$2:$B$1000 = $B17) * (df_proj!$C$2:$C$1000 = $D$2), 0), MATCH(TEXT(T$8, "####"), df_proj!$E$1:$AD$1,0)),5),MROUND(INDEX(df_proj!$E$2:$AD$1000, MATCH(1, ($B$2 = df_proj!$A$2:$A$1000) * (df_proj!$B$2:$B$1000 = $B17) * (df_proj!$C$2:$C$1000 = $D$2), 0), MATCH(TEXT(T$8, "####"), df_proj!$E$1:$AD$1,0)) * popn_fut!$C89/popn_fut!$E89,5))} -> #N/A | ... AL17: {=IFERROR(MROUND(INDEX(df_proj!$E$2:$AD$1000, MATCH(1, ($A$2 = df_proj!$A$2:$A$1000) * (df_proj!$B$2:$B$1000 = $B17) * (df_proj!$C$2:$C$1000 = $D$2), 0), MATCH(TEXT(AL$8, "####"), df_proj!$E$1:$AD$1,0)),5),MROUND(INDEX(df_proj!$E$2:$AD$1000, MATCH(1, ($B$2 = df_proj!$A$2:$A$1000) * (df_proj!$B$2:$B$1000 = $B17) * (df_proj!$C$2:$C$1000 = $D$2), 0), MATCH(TEXT(AL$8, "####"), df_proj!$E$1:$AD$1,0)) * popn_fut!$C89/popn_fut!$E89,5))} -> #N/A | AM17: =AM16+I17 -> #N/A | AP17: =AP16+W17 -> #N/A
A18: 40 | B18: 40 to 44 | D18: #N/A | I18: #N/A | M18: {=IFERROR(MROUND(INDEX(df_proj!$E$2:$AD$1000, MATCH(1, ($A$2 = df_proj!$A$2:$A$1000) * (df_proj!$B$2:$B$1000 = $B18) * (df_proj!$C$2:$C$1000 = $D$2), 0), MATCH(TEXT(M$8, "####"), df_proj!$E$1:$AD$1,0)),5),MROUND(INDEX(df_proj!$E$2:$AD$1000, MATCH(1, ($B$2 = df_proj!$A$2:$A$1000) * (df_proj!$B$2:$B$1000 = $B18) * (df_proj!$C$2:$C$1000 = $D$2), 0), MATCH(TEXT(M$8, "####"), df_proj!$E$1:$AD$1,0)) * popn_fut!$C90/popn_fut!$E90,5))} -> #N/A | N18: {=IFERROR(MROUND(INDEX(df_proj!$E$2:$AD$1000, MATCH(1, ($A$2 = df_proj!$A$2:$A$1000) * (df_proj!$B$2:$B$1000 = $B18) * (df_proj!$C$2:$C$1000 = $D$2), 0), MATCH(TEXT(N$8, "####"), df_proj!$E$1:$AD$1,0)),5),MROUND(INDEX(df_proj!$E$2:$AD$1000, MATCH(1, ($B$2 = df_proj!$A$2:$A$1000) * (df_proj!$B$2:$B$1000 = $B18) * (df_proj!$C$2:$C$1000 = $D$2), 0), MATCH(TEXT(N$8, "####"), df_proj!$E$1:$AD$1,0)) * popn_fut!$C90/popn_fut!$E90,5))} -> #N/A | O18: {=IFERROR(MROUND(INDEX(df_proj!$E$2:$AD$1000, MATCH(1, ($A$2 = df_proj!$A$2:$A$1000) * (df_proj!$B$2:$B$1000 = $B18) * (df_proj!$C$2:$C$1000 = $D$2), 0), MATCH(TEXT(O$8, "####"), df_proj!$E$1:$AD$1,0)),5),MROUND(INDEX(df_proj!$E$2:$AD$1000, MATCH(1, ($B$2 = df_proj!$A$2:$A$1000) * (df_proj!$B$2:$B$1000 = $B18) * (df_proj!$C$2:$C$1000 = $D$2), 0), MATCH(TEXT(O$8, "####"), df_proj!$E$1:$AD$1,0)) * popn_fut!$C90/popn_fut!$E90,5))} -> #N/A | P18: {=IFERROR(MROUND(INDEX(df_proj!$E$2:$AD$1000, MATCH(1, ($A$2 = df_proj!$A$2:$A$1000) * (df_proj!$B$2:$B$1000 = $B18) * (df_proj!$C$2:$C$1000 = $D$2), 0), MATCH(TEXT(P$8, "####"), df_proj!$E$1:$AD$1,0)),5),MROUND(INDEX(df_proj!$E$2:$AD$1000, MATCH(1, ($B$2 = df_proj!$A$2:$A$1000) * (df_proj!$B$2:$B$1000 = $B18) * (df_proj!$C$2:$C$1000 = $D$2), 0), MATCH(TEXT(P$8, "####"), df_proj!$E$1:$AD$1,0)) * popn_fut!$C90/popn_fut!$E90,5))} -> #N/A | Q18: {=IFERROR(MROUND(INDEX(df_proj!$E$2:$AD$1000, MATCH(1, ($A$2 = df_proj!$A$2:$A$1000) * (df_proj!$B$2:$B$1000 = $B18) * (df_proj!$C$2:$C$1000 = $D$2), 0), MATCH(TEXT(Q$8, "####"), df_proj!$E$1:$AD$1,0)),5),MROUND(INDEX(df_proj!$E$2:$AD$1000, MATCH(1, ($B$2 = df_proj!$A$2:$A$1000) * (df_proj!$B$2:$B$1000 = $B18) * (df_proj!$C$2:$C$1000 = $D$2), 0), MATCH(TEXT(Q$8, "####"), df_proj!$E$1:$AD$1,0)) * popn_fut!$C90/popn_fut!$E90,5))} -> #N/A | R18: {=IFERROR(MROUND(INDEX(df_proj!$E$2:$AD$1000, MATCH(1, ($A$2 = df_proj!$A$2:$A$1000) * (df_proj!$B$2:$B$1000 = $B18) * (df_proj!$C$2:$C$1000 = $D$2), 0), MATCH(TEXT(R$8, "####"), df_proj!$E$1:$AD$1,0)),5),MROUND(INDEX(df_proj!$E$2:$AD$1000, MATCH(1, ($B$2 = df_proj!$A$2:$A$1000) * (df_proj!$B$2:$B$1000 = $B18) * (df_proj!$C$2:$C$1000 = $D$2), 0), MATCH(TEXT(R$8, "####"), df_proj!$E$1:$AD$1,0)) * popn_fut!$C90/popn_fut!$E90,5))} -> #N/A | S18: {=IFERROR(MROUND(INDEX(df_proj!$E$2:$AD$1000, MATCH(1, ($A$2 = df_proj!$A$2:$A$1000) * (df_proj!$B$2:$B$1000 = $B18) * (df_proj!$C$2:$C$1000 = $D$2), 0), MATCH(TEXT(S$8, "####"), df_proj!$E$1:$AD$1,0)),5),MROUND(INDEX(df_proj!$E$2:$AD$1000, MATCH(1, ($B$2 = df_proj!$A$2:$A$1000) * (df_proj!$B$2:$B$1000 = $B18) * (df_proj!$C$2:$C$1000 = $D$2), 0), MATCH(TEXT(S$8, "####"), df_proj!$E$1:$AD$1,0)) * popn_fut!$C90/popn_fut!$E90,5))} -> #N/A | T18: {=IFERROR(MROUND(INDEX(df_proj!$E$2:$AD$1000, MATCH(1, ($A$2 = df_proj!$A$2:$A$1000) * (df_proj!$B$2:$B$1000 = $B18) * (df_proj!$C$2:$C$1000 = $D$2), 0), MATCH(TEXT(T$8, "####"), df_proj!$E$1:$AD$1,0)),5),MROUND(INDEX(df_proj!$E$2:$AD$1000, MATCH(1, ($B$2 = df_proj!$A$2:$A$1000) * (df_proj!$B$2:$B$1000 = $B18) * (df_proj!$C$2:$C$1000 = $D$2), 0), MATCH(TEXT(T$8, "####"), df_proj!$E$1:$AD$1,0)) * popn_fut!$C90/popn_fut!$E90,5))} -> #N/A | ... AL18: {=IFERROR(MROUND(INDEX(df_proj!$E$2:$AD$1000, MATCH(1, ($A$2 = df_proj!$A$2:$A$1000) * (df_proj!$B$2:$B$1000 = $B18) * (df_proj!$C$2:$C$1000 = $D$2), 0), MATCH(TEXT(AL$8, "####"), df_proj!$E$1:$AD$1,0)),5),MROUND(INDEX(df_proj!$E$2:$AD$1000, MATCH(1, ($B$2 = df_proj!$A$2:$A$1000) * (df_proj!$B$2:$B$1000 = $B18) * (df_proj!$C$2:$C$1000 = $D$2), 0), MATCH(TEXT(AL$8, "####"), df_proj!$E$1:$AD$1,0)) * popn_fut!$C90/popn_fut!$E90,5))} -> #N/A | AM18: =AM17+I18 -> #N/A | AP18: =AP17+W18 -> #N/A
